2023-06-22 22:45:21,965 INFO Running C++ tests for iteration 3
2023-06-22 22:45:22,695 INFO Started container return code: 0, 7e56b8d4811638281e58337bbdc77bc1f399b77416746f6aa21f4208403312b0
, 
2023-06-22 22:45:22,695 INFO Started: data/runs/run-20230622-224133/iteration-3-cpp/permutations_shared_computation.cpp, outfile: data/runs/run-20230622-224133/iteration-3-cpp/permutations_shared_computation_output_cpp-3.txt
2023-06-22 22:45:22,695 INFO Testing: data/runs/run-20230622-224133/iteration-3-cpp/permutations_shared_computation.cpp
2023-06-22 22:45:24,226 INFO Compile 0, , 
2023-06-22 22:45:24,228 INFO Started running
2023-06-22 22:45:26,917 INFO Terminated with 134 output:terminate called after throwing an instance of 'std::future_error'
  what():  std::future_error: Promise already satisfied
2023-06-22 22:45:26,918 INFO Getting the count failed iinc
2023-06-22 22:45:26,918 INFO generate_a_continue_file file: data/runs/run-20230622-224133/iteration-3-cpp/permutations_shared_computation.cpp continue_counter:1, count:1
2023-06-22 22:45:26,919 INFO found in: try { std::cout << "count:1 "; std::jthread t1(calculation1, std::ref(prom)) ;} catch (...) { std::cout << "fail" <<std::endl;}
2023-06-22 22:45:26,919 INFO loc : 1
2023-06-22 22:45:26,919 INFO continue_file : data/runs/run-20230622-224133/iteration-3-cpp/permutations_shared_computation_cont_1.cpp
2023-06-22 22:45:26,919 INFO Testing: data/runs/run-20230622-224133/iteration-3-cpp/permutations_shared_computation_cont_1.cpp
2023-06-22 22:45:28,476 INFO Compile 0, , 
2023-06-22 22:45:28,479 INFO Started running
2023-06-22 22:45:58,480 INFO Timeout
2023-06-22 22:45:58,660 INFO Terminating ./output 0, , 
2023-06-22 22:45:58,661 INFO Wrote partial result 
2023-06-22 22:45:58,661 INFO Getting the count failed iinc
2023-06-22 22:45:58,661 INFO generate_a_continue_file, data/runs/run-20230622-224133/iteration-3-cpp/permutations_shared_computation.cpp, 2, 2
2023-06-22 22:45:58,661 INFO generate_a_continue_file file: data/runs/run-20230622-224133/iteration-3-cpp/permutations_shared_computation.cpp continue_counter:2, count:2
2023-06-22 22:45:58,661 INFO found in: try { std::cout << "count:2 "; std::jthread t2(calculation2, std::ref(fut)) ;} catch (...) { std::cout << "fail" <<std::endl;}
2023-06-22 22:45:58,661 INFO loc : 2
2023-06-22 22:45:58,662 INFO continue_file : data/runs/run-20230622-224133/iteration-3-cpp/permutations_shared_computation_cont_2.cpp
2023-06-22 22:45:58,662 INFO Testing: data/runs/run-20230622-224133/iteration-3-cpp/permutations_shared_computation_cont_2.cpp
2023-06-22 22:46:00,227 INFO Compile 0, , 
2023-06-22 22:46:00,232 INFO Started running
2023-06-22 22:46:30,233 INFO Timeout
2023-06-22 22:46:30,391 INFO Terminating ./output 0, , 
2023-06-22 22:46:30,391 INFO Wrote partial result 
2023-06-22 22:46:30,391 INFO Getting the count failed iinc
2023-06-22 22:46:30,391 INFO generate_a_continue_file, data/runs/run-20230622-224133/iteration-3-cpp/permutations_shared_computation.cpp, 3, 3
2023-06-22 22:46:30,392 INFO generate_a_continue_file file: data/runs/run-20230622-224133/iteration-3-cpp/permutations_shared_computation.cpp continue_counter:3, count:3
2023-06-22 22:46:30,392 INFO found in: try { std::cout << "count:3 "; std::jthread t2(calculation2, std::ref(fut)) ;} catch (...) { std::cout << "fail" <<std::endl;}
2023-06-22 22:46:30,392 INFO loc : 3
2023-06-22 22:46:30,392 INFO continue_file : data/runs/run-20230622-224133/iteration-3-cpp/permutations_shared_computation_cont_3.cpp
2023-06-22 22:46:30,392 INFO Testing: data/runs/run-20230622-224133/iteration-3-cpp/permutations_shared_computation_cont_3.cpp
2023-06-22 22:46:31,867 INFO Compile 0, , 
2023-06-22 22:46:31,870 INFO Started running
2023-06-22 22:46:34,833 INFO Terminated with 134 output:terminate called after throwing an instance of 'std::future_error'
  what():  std::future_error: Promise already satisfied
2023-06-22 22:46:34,833 INFO Getting the count failed iinc
2023-06-22 22:46:34,834 INFO generate_a_continue_file file: data/runs/run-20230622-224133/iteration-3-cpp/permutations_shared_computation.cpp continue_counter:4, count:4
2023-06-22 22:46:34,834 INFO found in: try { std::cout << "count:4 "; std::jthread t1(calculation1, std::ref(prom)) ;} catch (...) { std::cout << "fail" <<std::endl;}
2023-06-22 22:46:34,834 INFO loc : 4
2023-06-22 22:46:34,834 INFO continue_file : data/runs/run-20230622-224133/iteration-3-cpp/permutations_shared_computation_cont_4.cpp
2023-06-22 22:46:34,834 INFO Testing: data/runs/run-20230622-224133/iteration-3-cpp/permutations_shared_computation_cont_4.cpp
2023-06-22 22:46:36,327 INFO Compile 0, , 
2023-06-22 22:46:36,330 INFO Started running
2023-06-22 22:46:37,462 INFO Succes, count:5
